<?xml version="1.0"?>
<sdf version="1.6">
  <model name="lrauv">
    <publish_render>true</publish_render>

    <!-- Body -->
    <link name="base_link">
      <pose>0 0 0 0 0 3.1415</pose>
      <inertial>
        <mass>147.8671</mass>
        <inertia>
          <ixx>3.000000</ixx>
          <ixy>0</ixy>
          <ixz>0</ixz>
          <iyy>41.980233</iyy>
          <iyz>0</iyz>
          <izz>41.980233</izz>
        </inertia>
      </inertial>
      <collision name="main_body_buoyancy">
        <geometry>
          <box>
            <size>2 0.3 0.2464451666666667</size>
          </box>
        </geometry>
      </collision>
      <visual name="visual">
        <pose>0 0 0 0 0 0</pose>
        <geometry>
          <mesh>
            <uri>meshes/tethys.dae</uri>
                        <scale>3 3 3</scale>
            <submesh>
              <name>Body</name>
              <center>false</center>
            </submesh>
          </mesh>
        </geometry>
        <material>
          <diffuse>1.0 1.0 1.0</diffuse>
          <specular>1.0 1.0 1.0</specular>
          <pbr>
            <metal>
              <albedo_map>materials/textures/Tethys_Albedo.png</albedo_map>
              <normal_map>materials/textures/Tethys_Normal.png</normal_map>
              <metalness_map>materials/textures/Tethys_Metalness.png</metalness_map>
              <roughness_map>materials/textures/Tethys_Roughness.png</roughness_map>
            </metal>
          </pbr>
        </material>
      </visual>

      <sensor name="imu_wamv_link" type="imu">
        <always_on>1</always_on>
        <update_rate>60</update_rate>
        <visualize>true</visualize>
        <topic>lrauv/imu</topic>
        <gz_frame_id>lrauv/base_link</gz_frame_id>
        <enable_metrics>true</enable_metrics>
        <imu>
          <linear_acceleration>
            <x>
              <noise type="gaussian">
                <mean>0</mean>
                <stddev>0</stddev>
                <dynamic_bias_stddev>0.2</dynamic_bias_stddev>
                <dynamic_bias_correlation_time>1</dynamic_bias_correlation_time>
              </noise>
            </x>
            <y>
              <noise type="gaussian">
                <mean>1</mean>
                <stddev>0</stddev>
                <dynamic_bias_stddev>0.2</dynamic_bias_stddev>
                <dynamic_bias_correlation_time>1</dynamic_bias_correlation_time>
              </noise>
            </y>
            <z>
              <noise type="gaussian">
                <mean>0</mean>
                <stddev>0</stddev>
                <dynamic_bias_stddev>0.2</dynamic_bias_stddev>
                <dynamic_bias_correlation_time>1</dynamic_bias_correlation_time>
              </noise>
            </z>
          </linear_acceleration>
          <angular_velocity>
            <x>
              <noise type="gaussian">
                <mean>0</mean>
                <stddev>0</stddev>
                <dynamic_bias_stddev>0.2</dynamic_bias_stddev>
                <dynamic_bias_correlation_time>1</dynamic_bias_correlation_time>
              </noise>
            </x>
            <y>
              <noise type="gaussian">
                <mean>0</mean>
                <stddev>0</stddev>
                <dynamic_bias_stddev>0.2</dynamic_bias_stddev>
                <dynamic_bias_correlation_time>1</dynamic_bias_correlation_time>
              </noise>
            </y>
            <z>
              <noise type="gaussian">
                <mean>0</mean>
                <stddev>0</stddev>
                <dynamic_bias_stddev>0.2</dynamic_bias_stddev>
                <dynamic_bias_correlation_time>1</dynamic_bias_correlation_time>
              </noise>
            </z>
          </angular_velocity>
          <orientation_reference_frame>
            <localization>ENU</localization>
            <custom_rpy parent_frame="linka">0 1 0</custom_rpy>
            <grav_dir_x parent_frame="linkb">0 0 1</grav_dir_x>
          </orientation_reference_frame>
          <enable_orientation>true</enable_orientation>
        </imu>
      </sensor>
      <sensor name="magnetometer" type="magnetometer">
        <always_on>1</always_on>
        <update_rate>100</update_rate>
        <visualize>true</visualize>
        <topic>lrauv/magnetometer</topic>
        <gz_frame_id>lrauv/base_link</gz_frame_id>
        <enable_metrics>true</enable_metrics>
        <magnetometer>
          <x>
            <noise type="gaussian">
              <mean>0.0</mean>
              <stddev>0.1</stddev>
            </noise>
          </x>
          <y>
            <noise type="gaussian">
              <mean>0.0</mean>
              <stddev>0.1</stddev>
            </noise>
          </y>
          <z>
            <noise type="gaussian">
              <mean>0.0</mean>
              <stddev>0.1</stddev>
            </noise>
          </z>
        </magnetometer>
      </sensor>
    </link>
    <!-- Horizontal fins -->
    <link name="horizontal_fins">
      <pose>-1.05 0 0 0 0 3.1415</pose>
      <inertial>
        <pose>0 0 0 1.57 0 0.5</pose>
        <mass>0.2</mass>
        <inertia>
          <ixx>0.0007924568755</ixx>
          <ixy>-0.0000000002674</ixy>
          <ixz>0.0003978158176</ixz>
          <iyy>0.0010546736475</iyy>
          <iyz>-0.0000000006729</iyz>
          <izz>0.0002633558262</izz>
        </inertia>
      </inertial>
      <collision name="collision_horizontal_fins">
        <geometry>
          <box>
            <size>0.1 0.1 0.02</size>
          </box>
        </geometry>
      </collision>
      <visual name="visual_horizontal_fins">
        <pose>-1.05 0 0 0 0 0</pose>
        <geometry>
          <mesh>
            <uri>meshes/tethys.dae</uri>
            <submesh>
              <name>Fins_Horizontal</name>
              <center>false</center>
            </submesh>
          </mesh>
        </geometry>
        <material>
          <diffuse>1.0 1.0 1.0</diffuse>
          <specular>1.0 1.0 1.0</specular>
          <pbr>
            <metal>
              <albedo_map>materials/textures/Tethys_Albedo.png</albedo_map>
              <normal_map>materials/textures/Tethys_Normal.png</normal_map>
              <metalness_map>materials/textures/Tethys_Metalness.png</metalness_map>
              <roughness_map>materials/textures/Tethys_Roughness.png</roughness_map>
            </metal>
          </pbr>
        </material>
      </visual>
    </link>
    <!-- Vertical fins -->
    <link name="vertical_fins">
      <pose>-1.05 0 0 0 0 3.1415</pose>
      <inertial>
        <mass>0.2</mass>
        <inertia>
          <ixx>0.0007924568755</ixx>
          <ixy>-0.0000000002674</ixy>
          <ixz>0.0003978158176</ixz>
          <iyy>0.0010546736475</iyy>
          <iyz>-0.0000000006729</iyz>
          <izz>0.0002633558262</izz>
        </inertia>
      </inertial>
      <collision name="collision_vertical_fins">
        <geometry>
          <box>
            <size>0.1 0.1 0.02</size>
          </box>
        </geometry>
      </collision>
      <visual name="visual_vertical_fins">
        <pose>-1.05 0 0 0 0 0</pose>
        <geometry>
          <mesh>
            <uri>meshes/tethys.dae</uri>
            <submesh>
              <name>Fins_vertical</name>
              <center>false</center>
            </submesh>
          </mesh>
        </geometry>
        <material>
          <diffuse>1.0 1.0 1.0</diffuse>
          <specular>1.0 1.0 1.0</specular>
          <pbr>
            <metal>
              <albedo_map>materials/textures/Tethys_Albedo.png</albedo_map>
              <normal_map>materials/textures/Tethys_Normal.png</normal_map>
              <metalness_map>materials/textures/Tethys_Metalness.png</metalness_map>
              <roughness_map>materials/textures/Tethys_Roughness.png</roughness_map>
            </metal>
          </pbr>
        </material>
      </visual>
    </link>
    <!-- Propeller -->
    <link name="propeller">
      <pose>-1.43162 0 0 0 0 0</pose>
      <inertial>
        <pose>0 0 0 0 0 0</pose>
        <mass>0.09</mass>
        <inertia>
          <ixx>0.000143971303</ixx>
          <ixy>0.000000000008</ixy>
          <ixz>-0.000000000224</ixz>
          <iyy>0.000140915448</iyy>
          <iyz>-0.000025236433</iyz>
          <izz>0.000033571862</izz>
        </inertia>
      </inertial>
      <collision name="collision_propeller">
        <geometry>
          <box>
            <size>0.03 0.1 0.03</size>
          </box>
        </geometry>
      </collision>
      <visual name="visual_propeller">
        <pose>-1.43162 0 0 0 0 0</pose>
        <geometry>
          <mesh>
            <uri>meshes/tethys.dae</uri>
            <submesh>
              <name>Prop</name>
              <center>false</center>
            </submesh>
          </mesh>
        </geometry>
        <material>
          <diffuse>1.0 1.0 1.0</diffuse>
          <specular>1.0 1.0 1.0</specular>
          <pbr>
            <metal>
              <albedo_map>materials/textures/Tethys_Albedo.png</albedo_map>
              <normal_map>materials/textures/Tethys_Normal.png</normal_map>
              <metalness_map>materials/textures/Tethys_Metalness.png</metalness_map>
              <roughness_map>materials/textures/Tethys_Roughness.png</roughness_map>
            </metal>
          </pbr>
        </material>
      </visual>
    </link>
    <!-- Joints -->
    <joint name="horizontal_fins_joint" type="revolute">
      <pose>0 0 0 0 0 0</pose>
      <parent>base_link</parent>
      <child>horizontal_fins</child>
      <axis>
        <xyz>0 1 0</xyz>
        <limit>
          <lower>-0.261799</lower>
          <upper>0.261799</upper>
          <effort>-1</effort>
          <velocity>-1</velocity>
        </limit>
      </axis>
    </joint>
    <joint name="vertical_fins_joint" type="revolute">
      <pose>0 0 0 0 0 0</pose>
      <parent>base_link</parent>
      <child>vertical_fins</child>
      <axis>
        <xyz>0 0 1</xyz>
        <limit>
          <lower>-0.261799</lower>
          <upper>0.261799</upper>
          <effort>-1</effort>
          <velocity>-1</velocity>
        </limit>
      </axis>
    </joint>
    <joint name="propeller_joint" type="revolute">
      <pose>0 0 0 0 0 0</pose>
      <parent>base_link</parent>
      <child>propeller</child>
      <axis>
        <xyz>1 0 0</xyz>
        <limit>
          <lower>-1e+12</lower>
          <upper>1e+12</upper>
          <effort>-1</effort>
          <velocity>-1</velocity>
        </limit>
      </axis>
    </joint>

    <!-- Start of plugin -->
    <plugin filename="gz-sim-thruster-system" name="gz::sim::systems::Thruster">
      <use_angvel_cmd>0</use_angvel_cmd>
      <joint_name>propeller_joint</joint_name>
      <thrust_coefficient>0.004422</thrust_coefficient>
      <fluid_density>1000</fluid_density>
        <velocity_control>true</velocity_control>
      <propeller_diameter>0.2</propeller_diameter>
    </plugin>

    <!-- The Lift acting on the controlled surfaces -->
    <plugin filename="gz-sim-lift-drag-system" name="gz::sim::systems::LiftDrag">
      <air_density>1000</air_density>
      <cla>4.13</cla>
      <cla_stall>-1.1</cla_stall>
      <cda>0.2</cda>
      <cda_stall>0.03</cda_stall>
      <alpha_stall>0.17</alpha_stall>
      <a0>0</a0>
      <area>0.0244</area>
      <upward>0 1 0</upward>
      <forward>1 0 0</forward>
      <link_name>vertical_fins</link_name>
      <cp>0 0 0</cp>
    </plugin>
    <plugin filename="gz-sim-lift-drag-system" name="gz::sim::systems::LiftDrag">
      <air_density>1000</air_density>
      <cla>4.13</cla>
      <cla_stall>-1.1</cla_stall>
      <cda>0.2</cda>
      <cda_stall>0.03</cda_stall>
      <alpha_stall>0.17</alpha_stall>
      <a0>0</a0>
      <area>0.0244</area>
      <upward>0 0 1</upward>
      <forward>1 0 0</forward>
      <link_name>horizontal_fins</link_name>
      <cp>0 0 0</cp>
    </plugin>

    <!-- The movement of the controlled surfaces -->
    <plugin filename="gz-sim-joint-position-controller-system" name="gz::sim::systems::JointPositionController">
      <joint_name>horizontal_fins_joint</joint_name>
      <p_gain>0.1</p_gain>
    </plugin>
    <plugin filename="gz-sim-joint-position-controller-system" name="gz::sim::systems::JointPositionController">
      <joint_name>vertical_fins_joint</joint_name>
      <p_gain>0.1</p_gain>
    </plugin>
  </model>
</sdf>
